Workbook

Sheet 00_COVER_LOGIN
A1: SRIYANTO RBI MINI APM SYSTEM | I1: Patuha Unit-2 | Secure Access Gateway
B7: RBI MINI APM
G8: LOGIN ACCESS
G10: Enter credentials to unlock the RBI model environment.
B12: Risk Based Inspection • Asset Integrity Corrosion Loop • Risk Matrix • L3 Readiness
G13: Username | H13: admin
G15: Password | H15: 1234
B17: GDE Matrix | D17: P&ID Alignment
G18: LOGIN | J18: CLEAR
B20: ECA Gate | D20: L3 Thickness
G21: Status: Not logged in
B24: Developed by Adam SRIYANTO RBI System | G24: Default test access: admin / 1234 | Save as .xlsm and import VBA
A34: © SRIYANTO RBI Mini APM System • Confidential – Internal Use

Sheet 00_USER_GUIDE_FLOW
A1: RBI MINI APM SYSTEM – USER FLOW GUIDE
A2: Quick operating guide for controlled data input, automated RBI preview, risk matrix update, reconciliation, and optional L3 thickness update.
B4: MAIN OPERATION FLOW | J4: QUICK CHECKLIST
C6: START Open workbook and check dashboard status | J6: Before using macro Save as .xlsm Enable Content Import .bas macro
E8: ↓
C9: 1. INPUT ASSET Use 00_INPUT_CONTROL_PANEL Do not type directly into database
J11: Before ADD ASSET Validation = OK Duplicate = NO Risk preview reviewed
E12: ↓
C13: 2. AUTO ENGINE PREVIEW Corrosion Loop Damage Mechanism PoF / CoF Risk / ECA / Scope
J16: After ADD ASSET Asset appears in database Risk engine updated Inspection strategy updated
E17: ↓
C18: 3. VALIDATION CHECK Missing data Duplicate tag Logic consistency CUI / material warnings
E21: ↓ | J21: Before reporting Reconciliation = PASS Coverage = 100% Matrix counts match
C22: VALID? If NOT valid → fix input If valid → continue
H23: NO → Fix Input
H24: YES → Continue
E25: ↓
C26: 4. CLICK ADD ASSET Run VBA macro after saving as .xlsm | J26: L3 use rule Only input thickness when UT / baseline data exists Do not force L3 for greenfield data
E29: ↓
C30: 5. DATABASE UPDATE 01_ASSET_INPUT_FULL 08_GDE_RISK_ENGINE 09_INSPECTION_STRATEGY 10_L3_UPGRADE_INPUT (if completed)
J31: IMPORTANT RULES
J32: 1. Do NOT input directly to 01_ASSET_INPUT_FULL unless debugging. 2. Always check validation before using ADD ASSET. 3. Reconciliation PASS is mandatory before client presentation. 4. GDE-approved risk matrix/procedure remains final authority. 5. L3 thickness section is optional until UT data is available.
E34: ↓
C35: 6. RISK MATRIX UPDATE 14_GDE_RISK_MATRIX_DASHBOARD Counts update from linked risk engine
E38: ↓
C39: 7. RECONCILIATION CHECK 16_RECONCILIATION_CHECK Coverage must be 100%
E42: ↓
C43: PASS? If CHECK REQUIRED → debug first If PASS → model is ready
J44: COLOR LEGEND
J45: Blue | K45: User Input / L3 Input
E46: ↓ | J46: Yellow | K46: Auto Engine / Risk Matrix
C47: 8. OPTIONAL L3 THICKNESS Input thickness only when UT data exists Calculate CR / RL / L3 PoF | J47: Orange | K47: Validation / Caution
J48: Green | K48: OK / Action Complete
J49: Red | K49: Critical / Do Not Proceed
E50: ↓ | J50: Gray | K50: Start / End / Static Info
C51: END Ready for review / meeting / report extraction
B55: NAVIGATION
B56: Input Control Panel | D56: Dashboard | F56: Risk Matrix Dashboard | H56: Reconciliation Check | J56: Asset Database | L56: =HYPERLINK("#'18_GB_CODE_MASTER'!A1","GB Code Master") -> GB Code Master

Sheet 00_INPUT_CONTROL_PANEL
A1: Patuha Unit-2 RBI Mini APM System — Input Control Panel | Z1: User Guide
A2: Controlled input → live RBI preview → validation → database update. Designed for GE-style / APM-style RBI workflow.
B4: INPUT FORM | E4: AUTO ENGINE — READ ONLY PREVIEW | J4: LIVE SUMMARY | M4: SAFE INPUT MODE — SAVE / SEARCH / UPDATE RULES
B5: Asset Tag | C5: P2LBA99 BR999 | E5: Corrosion Loop ID | F5: =UPPER("CL-"&SUBSTITUTE(C7,"/","")&"-"&C8&"-"&SUBSTITUTE(C9," ","")&"-"&C11&"-"&C10) -> CL-SAGS-LBA-STEAM-CS-LG | J5: Total Assets | K5: =COUNTA('01_ASSET_INPUT_FULL'!A:A)-1 -> 414
B6: Asset Type | C6: Piping | E6: Dominant Damage Mechanism | F6: =IF(AND(C9="Steam",C10="LG",C11="CS"),"CO2 corrosion; Erosion-corrosion/FAC; CUI",IF(AND(C9="Steam",C10="V"),"CUI; Atmospheric corrosion; localized erosion",IF(C9="NCG","H2S / sour corrosion; CLSCC if chloride; CUI",IF(C9="Cooling Water","MIC; oxygen corrosion; fouling",IF(OR(C9="Condensate",C9="Condensate Steam"),"CO2 condensate corrosion; MIC; oxygen corrosion","General external corrosion / CUI if insulated"))))) -> CO2 corrosion; Erosion-corrosion/FAC; CUI | J6: Piping Assets | K6: =COUNTIF('01_ASSET_INPUT_FULL'!B:B,"Piping") -> 345 | M6: Command | N6: When to use | O6: Blocking Rule | P6: Database Impact
B7: System | C7: SAGS | E7: PoF Score | F7: =IF(AND(C9="Steam",C10="LG",C11="CS"),4,IF(AND(C9="Steam",C10="V",C11="CS"),2,IF(AND(OR(C9="Condensate",C9="Condensate Steam"),C11="CS"),4,IF(AND(C9="NCG",C11="CS"),4,IF(C9="NCG",2,IF(AND(C9="Cooling Water",C11="CS"),3,2)))))) -> 4 | J7: Equipment Assets | K7: =COUNTIF('01_ASSET_INPUT_FULL'!B:B,"Equipment") -> 68 | M7: SEARCH / LOAD | N7: Asset Tag already exists and needs review/edit | O7: Asset Tag must exist | P7: Loads existing row into form; no database change
B8: Process Code | C8: LBA | E8: CoF Score | F8: =IF(C14="YES",5,IF(OR(C8="LBA",C8="MAC"),5,IF(OR(C8="MAG",C8="MAJ"),4,IF(OR(C8="PAB",C8="PAC",C8="PAD",C8="PAE",C8="PCB"),3,2)))) -> 5 | J8: Preview Risk | K8: =F9 -> Extreme High | M8: SAVE NEW | N8: New asset only | O8: Reject if Asset Tag already exists | P8: Appends new row to 01_ASSET_INPUT_FULL
B9: Fluid / Service | C9: Steam | E9: Risk Level | F9: =IF(OR(AND(F7>=4,F8>=4),AND(F7=5,F8>=3)),"Extreme High",IF(OR(AND(F7>=3,F8>=3),AND(F8=5,F7>=2)),"High",IF(OR(F7>=2,F8>=2),"Medium","Low"))) -> Extreme High | G9: =F9 -> Extreme High | J9: Preview ECA | K9: =F10 -> C1 | M9: UPDATE EXISTING | N9: Edit loaded asset | O9: Requires SEARCH / LOAD first | P9: Updates only the matched row
B10: Phase | C10: LG | E10: ECA Category | F10: =IF(F8>=4,"C1",IF(F8=3,"C2","C3")) -> C1 | J10: Preview Scope | K10: =F13 -> IN | M10: CLEAR FORM | N10: Reset input form | O10: None | P10: No database change
B11: Material | C11: CS | E11: Inspection Method | F11: =IF(F9="Extreme High","UT Scan + VT + TML baseline",IF(F9="High","UT / VT + targeted TML",IF(F9="Medium","VT + sampling UT","Routine VT"))) -> UT Scan + VT + TML baseline | M11: CANCEL EDIT | N11: Exit edit mode | O11: None | P11: No database change
B12: Size (inch) | C12: 12 | E12: Inspection Interval (yr) | F12: =IF(F9="Extreme High",0.5,IF(F9="High",0.5,IF(F9="Medium",1,3))) -> 0.5
B13: Is Insulated? | C13: YES | E13: RBI Scope | F13: =IF(OR(C11="FRP",C11="HDPE"),"LIMITED",IF(OR(F10="C1",F10="C2"),"IN","OUT")) -> IN
B14: Service Critical? | C14: YES | E14: Data Quality Score | F14: =ROUND(COUNTA(C5:C15)/11,2) -> 1
B15: P&ID Reference | C15: PTH2-PR-LBA-PID-IKT-50002 | E15: Control Status | F15: =IF(COUNTIF('01_ASSET_INPUT_FULL'!A:A,C5)>0,"BLOCKED - DUPLICATE TAG",IF(F14<0.8,"CHECK - INCOMPLETE DATA","READY TO SAVE NEW")) -> READY TO SAVE NEW
B16: Description / Notes | C16: New asset input preview
B19: VALIDATION PANEL | J19: DATA QUALITY
B20: Asset Tag filled | C20: =IF(C5="","❌ Missing","✔ OK") -> ✔ OK | F20: Rule | G20: Live check | J20: Required fields filled | K20: =COUNTA(C5:C11)+COUNTA(C13:C14) -> 9
B21: Asset Tag unique | C21: =IF(COUNTIF('01_ASSET_INPUT_FULL'!A:A,C5)>0,"⚠ Existing - use UPDATE","✔ New Tag") -> ✔ New Tag | F21: Rule | G21: Live check | J21: Total required fields | K21: 9
B22: Asset Type valid | C22: =IF(OR(C6="Piping",C6="Equipment",C6="Component"),"✔ OK","❌ Invalid") -> ✔ OK | F22: Rule | G22: Live check | J22: Data Quality | K22: =ROUND(K20/K21,2) -> 1
B23: Fluid filled | C23: =IF(C9="","❌ Missing","✔ OK") -> ✔ OK | F23: Rule | G23: Live check | J23: Duplicate Count | K23: =COUNTIF('01_ASSET_INPUT_FULL'!A:A,C5) -> 0
B24: Phase consistent | C24: =IF(AND(OR(C9="Steam",C9="NCG",C9="Condensate Steam"),C10=""),"⚠ Phase required",IF(AND(C9="Cooling Water",C10="V"),"⚠ Check phase","✔ OK")) -> ✔ OK | F24: Rule | G24: Live check | J24: Input Health | K24: =IF(K22>=0.9,"Strong",IF(K22>=0.7,"Moderate","Weak")) -> Strong
B25: Material/service consistency | C25: =IF(AND(C9="NCG",C11="CS"),"⚠ CS in NCG service",IF(AND(C9="Steam",OR(C11="FRP",C11="HDPE")),"❌ Invalid material for steam","✔ OK")) -> ✔ OK | F25: Rule | G25: Live check
B26: Insulation/CUI flag | C26: =IF(AND(C13="YES",OR(C11="CS",C11="SS316L",C11="SS304L",C11="Carbon Steel",C11="API5L GR.B")),"⚠ CUI screening required","✔ OK") -> ⚠ CUI screening required | F26: Rule | G26: Live check
B27: Ready to Add | C27: =IF(AND(C5<>"",COUNTIF('01_ASSET_INPUT_FULL'!A:A,C5)=0,F14>=0.8),"✔ READY TO SAVE NEW",IF(COUNTIF('01_ASSET_INPUT_FULL'!A:A,C5)>0,"⚠ EXISTING - LOAD/UPDATE","❌ NOT READY")) -> ✔ READY TO SAVE NEW | F27: Rule | G27: Live check
J28: How to use: 1) Fill INPUT FORM. 2) Review AUTO ENGINE and VALIDATION PANEL. 3) If status is READY TO ADD, run ADD ASSET macro. Professional rule: Do not bypass validation. Any new asset should enter through this control panel.
B31: ACTION PANEL — SAFE DATABASE COMMANDS
B33: SEARCH / LOAD | D33: SAVE NEW | F33: UPDATE EXISTING | H33: CLEAR FORM | J33: CANCEL EDIT
B37: Database Target | C37: 01_ASSET_INPUT_FULL | E37: Edit Mode Row
B38: Macro Status | C38: VBA-ready. Use SEARCH/LOAD before UPDATE. SAVE NEW appends a new row only. | E38: Loaded Asset Tag
B40: L3 THICKNESS / CORROSION RATE INPUT — OPTIONAL FUTURE QUANTITATIVE RBI | J40: L3 INPUT VALIDATION
B41: t_nominal (mm) | E41: CR_LT (mm/yr) | F41: =IFERROR(($C$42-$C$43)/MAX(1,($C$46-$C$47)/365),"") -> 0 | J41: Thickness complete | K41: =IF(COUNTA(C41:C45)<5,"⚠ Incomplete","✔ OK") -> ⚠ Incomplete
B42: t_initial (mm) | E42: CR_ST (mm/yr) | F42: =IFERROR(($C$45-$C$43)/MAX(1,($C$46-$C$47)/365),"") -> 0 | J42: Date complete | K42: =IF(COUNTA(C46:C47)<2,"⚠ Date incomplete","✔ OK") -> ⚠ Date incomplete
B43: t_actual (mm) | E43: Governing CR (mm/yr) | F43: =IFERROR(MAX(F41,F42),"") -> 0 | J43: Actual ≥ t_min | K43: =IF(C43="","⚠ No actual",IF(C43>=C44,"✔ OK","❌ Below t_min")) -> ⚠ No actual
B44: t_min_required (mm) | E44: Remaining Life (yr) | F44: =IFERROR(($C$43-$C$44)/F43,"") | J44: Date sequence | K44: =IF(OR(C46="",C47=""),"⚠ No dates",IF(C46>C47,"✔ OK","❌ Check dates")) -> ⚠ No dates
B45: t_previous (mm) | E45: L3 PoF Score | F45: =IF(F44="","",IF(F44<=1,5,IF(F44<=2,4,IF(F44<=5,3,IF(F44<=10,2,1))))) | J45: CR valid | K45: =IF(F43="","⚠ No CR",IF(F43>0,"✔ OK","⚠ Zero/negative CR")) -> ⚠ Zero/negative CR
B46: Inspection Date | E46: L3 Risk Level | F46: =IF(F45="","",IF(OR(AND(F45>=4,$F$8>=4),AND(F45=5,$F$8>=3)),"Extreme High",IF(OR(AND(F45>=3,$F$8>=3),AND($F$8=5,F45>=2)),"High",IF(OR(F45>=2,$F$8>=2),"Medium","Low"))))
B47: Previous Inspection Date | E47: L3 Status | F47: =IF(COUNTA($C$41:$C$47)<7,"L3 DATA INCOMPLETE",IF(F44<0,"CHECK THICKNESS INPUT","L3 PREVIEW READY")) -> L3 DATA INCOMPLETE
B49: Use this L3 section only when thickness data is available. For current greenfield/pre-baseline condition, keep L3 fields blank and use Level-2 RBI. After baseline UT, these inputs can drive corrosion rate, remaining life, and future Level-3 PoF update. | J49: RECONCILIATION
J50: Risk Engine | K50: ='16_RECONCILIATION_CHECK'!C6 -> 414
J51: Matrix Count | K51: ='16_RECONCILIATION_CHECK'!C8 -> 413
...

Sheet 00_DASHBOARD
A1: RBI MINI APM SYSTEM | PATUHA UNIT-2 | Z1: User Guide
A3: Executive dashboard — linked KPI, risk distribution, model health, and GDE reference basis
B5: TOTAL ASSETS | E5: PIPING ASSETS | H5: EQUIPMENT ASSETS | K5: CORROSION LOOPS | N5: RECONCILIATION
B6: =COUNTA('01_ASSET_INPUT_FULL'!A:A)-1 -> 414 | E6: =COUNTIF('01_ASSET_INPUT_FULL'!B:B,"Piping") -> 345 | H6: =COUNTIF('01_ASSET_INPUT_FULL'!B:B,"Equipment") -> 68 | K6: =COUNTA('04_CORROSION_LOOP_MODEL'!A:A)-1 -> 99 | N6: ='16_RECONCILIATION_CHECK'!C13 -> CHECK REQUIRED
B9: =HYPERLINK("#'00_INPUT_CONTROL_PANEL'!A1","INPUT") -> INPUT | D9: =HYPERLINK("#'08_GDE_RISK_ENGINE'!A1","RISK ENGINE") -> RISK ENGINE | F9: =HYPERLINK("#'14_GDE_RISK_MATRIX_DASHBOARD'!A1","RISK MATRIX") -> RISK MATRIX | H9: =HYPERLINK("#'16_RECONCILIATION_CHECK'!A1","RECONCILIATION") -> RECONCILIATION | J9: =HYPERLINK("#'00_USER_GUIDE_FLOW'!A1","USER GUIDE") -> USER GUIDE | L9: =HYPERLINK("#'18_GB_CODE_MASTER'!A1","GB CODE MASTER") -> GB CODE MASTER
B12: Risk Distribution | I12: Asset Split by System | O12: Model Health
B13: Risk Level | C13: Count | D13: % | I13: System | J13: Count | O13: Metric | Q13: Value
B14: Extreme High | C14: =COUNTIF('08_GDE_RISK_ENGINE'!G:G,"Extreme High") -> 23 | D14: =IFERROR(C14/SUM($C$14:$C$17),0) -> 0.055690073 | I14: SAGS | J14: =COUNTIF('01_ASSET_INPUT_FULL'!D:D,"SAGS") -> 105 | O14: Risk Engine | Q14: ='16_RECONCILIATION_CHECK'!C6 -> 414
B15: High | C15: =COUNTIF('08_GDE_RISK_ENGINE'!G:G,"High") -> 261 | D15: =IFERROR(C15/SUM($C$14:$C$17),0) -> 0.63196126 | I15: Power Block | J15: =COUNTIF('01_ASSET_INPUT_FULL'!D:D,"Power Block") -> 65 | O15: Matrix Count | Q15: ='16_RECONCILIATION_CHECK'!C8 -> 413
B16: Medium | C16: =COUNTIF('08_GDE_RISK_ENGINE'!G:G,"Medium") -> 70 | D16: =IFERROR(C16/SUM($C$14:$C$17),0) -> 0.16949153 | I16: BOP/Utility | J16: =COUNTIF('01_ASSET_INPUT_FULL'!D:D,"BOP/Utility") -> 230 | O16: Coverage | Q16: ='16_RECONCILIATION_CHECK'!C11 -> 0.99758454
B17: Low | C17: =COUNTIF('08_GDE_RISK_ENGINE'!G:G,"Low") -> 59 | D17: =IFERROR(C17/SUM($C$14:$C$17),0) -> 0.14285714 | I17: Equipment | J17: =COUNTIF('01_ASSET_INPUT_FULL'!D:D,"Equipment") -> 6 | O17: Status | Q17: ='16_RECONCILIATION_CHECK'!C13 -> CHECK REQUIRED
B20: Top Risk Assets — current model output
B21: Asset Tag | C21: Type | D21: System | E21: Process | F21: Fluid | G21: State | H21: Material | I21: Loop / Model | J21: PoF | K21: CoF | L21: Risk | M21: Interval
B22: ='08_GDE_RISK_ENGINE'!A4 -> P2LBA11 BR001 | C22: ='08_GDE_RISK_ENGINE'!B4 -> Piping | D22: ='08_GDE_RISK_ENGINE'!C4 -> SAGS | E22: =IFERROR(VLOOKUP(B22,'01_ASSET_INPUT_FULL'!A:U,5,FALSE),"") -> LBA | F22: =IFERROR(VLOOKUP(B22,'01_ASSET_INPUT_FULL'!A:U,16,FALSE),"") -> Steam | G22: =IFERROR(VLOOKUP(B22,'01_ASSET_INPUT_FULL'!A:U,17,FALSE),"") -> LG | H22: =IFERROR(VLOOKUP(B22,'01_ASSET_INPUT_FULL'!A:U,12,FALSE),"") -> CS | I22: ='08_GDE_RISK_ENGINE'!D4 -> CL-SAGS-LBA-STEAM-CS-LG-T3_150C_PLUS | J22: ='08_GDE_RISK_ENGINE'!E4 -> 4 | K22: ='08_GDE_RISK_ENGINE'!F4 -> 5 | L22: ='08_GDE_RISK_ENGINE'!G4 -> Extreme High | M22: =IFERROR(VLOOKUP(B22,'09_INSPECTION_STRATEGY'!A:G,7,FALSE),"") -> 0.5
B23: ='08_GDE_RISK_ENGINE'!A5 -> P2LBA11 BR501 | C23: ='08_GDE_RISK_ENGINE'!B5 -> Piping | D23: ='08_GDE_RISK_ENGINE'!C5 -> SAGS | E23: =IFERROR(VLOOKUP(B23,'01_ASSET_INPUT_FULL'!A:U,5,FALSE),"") -> LBA | F23: =IFERROR(VLOOKUP(B23,'01_ASSET_INPUT_FULL'!A:U,16,FALSE),"") -> Steam | G23: =IFERROR(VLOOKUP(B23,'01_ASSET_INPUT_FULL'!A:U,17,FALSE),"") -> LG | H23: =IFERROR(VLOOKUP(B23,'01_ASSET_INPUT_FULL'!A:U,12,FALSE),"") -> CS | I23: ='08_GDE_RISK_ENGINE'!D5 -> CL-SAGS-LBA-STEAM-CS-LG-T3_150C_PLUS | J23: ='08_GDE_RISK_ENGINE'!E5 -> 4 | K23: ='08_GDE_RISK_ENGINE'!F5 -> 5 | L23: ='08_GDE_RISK_ENGINE'!G5 -> Extreme High | M23: =IFERROR(VLOOKUP(B23,'09_INSPECTION_STRATEGY'!A:G,7,FALSE),"") -> 0.5
B24: ='08_GDE_RISK_ENGINE'!A6 -> P2LBA11 BR011 | C24: ='08_GDE_RISK_ENGINE'!B6 -> Piping | D24: ='08_GDE_RISK_ENGINE'!C6 -> SAGS | E24: =IFERROR(VLOOKUP(B24,'01_ASSET_INPUT_FULL'!A:U,5,FALSE),"") -> LBA | F24: =IFERROR(VLOOKUP(B24,'01_ASSET_INPUT_FULL'!A:U,16,FALSE),"") -> Steam | G24: =IFERROR(VLOOKUP(B24,'01_ASSET_INPUT_FULL'!A:U,17,FALSE),"") -> LG | H24: =IFERROR(VLOOKUP(B24,'01_ASSET_INPUT_FULL'!A:U,12,FALSE),"") -> CS | I24: ='08_GDE_RISK_ENGINE'!D6 -> CL-SAGS-LBA-STEAM-CS-LG-T3_150C_PLUS | J24: ='08_GDE_RISK_ENGINE'!E6 -> 4 | K24: ='08_GDE_RISK_ENGINE'!F6 -> 5 | L24: ='08_GDE_RISK_ENGINE'!G6 -> Extreme High | M24: =IFERROR(VLOOKUP(B24,'09_INSPECTION_STRATEGY'!A:G,7,FALSE),"") -> 0.5
B25: ='08_GDE_RISK_ENGINE'!A7 -> P2LBA11 BR003 | C25: ='08_GDE_RISK_ENGINE'!B7 -> Piping | D25: ='08_GDE_RISK_ENGINE'!C7 -> SAGS | E25: =IFERROR(VLOOKUP(B25,'01_ASSET_INPUT_FULL'!A:U,5,FALSE),"") -> LBA | F25: =IFERROR(VLOOKUP(B25,'01_ASSET_INPUT_FULL'!A:U,16,FALSE),"") -> Steam | G25: =IFERROR(VLOOKUP(B25,'01_ASSET_INPUT_FULL'!A:U,17,FALSE),"") -> LG | H25: =IFERROR(VLOOKUP(B25,'01_ASSET_INPUT_FULL'!A:U,12,FALSE),"") -> CS | I25: ='08_GDE_RISK_ENGINE'!D7 -> CL-SAGS-LBA-STEAM-CS-LG-T3_150C_PLUS | J25: ='08_GDE_RISK_ENGINE'!E7 -> 4 | K25: ='08_GDE_RISK_ENGINE'!F7 -> 5 | L25: ='08_GDE_RISK_ENGINE'!G7 -> Extreme High | M25: =IFERROR(VLOOKUP(B25,'09_INSPECTION_STRATEGY'!A:G,7,FALSE),"") -> 0.5
B26: ='08_GDE_RISK_ENGINE'!A8 -> P2LBA11 BR010 | C26: ='08_GDE_RISK_ENGINE'!B8 -> Piping | D26: ='08_GDE_RISK_ENGINE'!C8 -> SAGS | E26: =IFERROR(VLOOKUP(B26,'01_ASSET_INPUT_FULL'!A:U,5,FALSE),"") -> LBA | F26: =IFERROR(VLOOKUP(B26,'01_ASSET_INPUT_FULL'!A:U,16,FALSE),"") -> Steam | G26: =IFERROR(VLOOKUP(B26,'01_ASSET_INPUT_FULL'!A:U,17,FALSE),"") -> LG | H26: =IFERROR(VLOOKUP(B26,'01_ASSET_INPUT_FULL'!A:U,12,FALSE),"") -> CS | I26: ='08_GDE_RISK_ENGINE'!D8 -> CL-SAGS-LBA-STEAM-CS-LG-T3_150C_PLUS | J26: ='08_GDE_RISK_ENGINE'!E8 -> 4 | K26: ='08_GDE_RISK_ENGINE'!F8 -> 5 | L26: ='08_GDE_RISK_ENGINE'!G8 -> Extreme High | M26: =IFERROR(VLOOKUP(B26,'09_INSPECTION_STRATEGY'!A:G,7,FALSE),"") -> 0.5
B27: ='08_GDE_RISK_ENGINE'!A9 -> P2LBA11 BR301 | C27: ='08_GDE_RISK_ENGINE'!B9 -> Piping | D27: ='08_GDE_RISK_ENGINE'!C9 -> SAGS | E27: =IFERROR(VLOOKUP(B27,'01_ASSET_INPUT_FULL'!A:U,5,FALSE),"") -> LBA | F27: =IFERROR(VLOOKUP(B27,'01_ASSET_INPUT_FULL'!A:U,16,FALSE),"") -> Steam | G27: =IFERROR(VLOOKUP(B27,'01_ASSET_INPUT_FULL'!A:U,17,FALSE),"") -> LG | H27: =IFERROR(VLOOKUP(B27,'01_ASSET_INPUT_FULL'!A:U,12,FALSE),"") -> CS | I27: ='08_GDE_RISK_ENGINE'!D9 -> CL-SAGS-LBA-STEAM-CS-LG-T3_150C_PLUS | J27: ='08_GDE_RISK_ENGINE'!E9 -> 4 | K27: ='08_GDE_RISK_ENGINE'!F9 -> 5 | L27: ='08_GDE_RISK_ENGINE'!G9 -> Extreme High | M27: =IFERROR(VLOOKUP(B27,'09_INSPECTION_STRATEGY'!A:G,7,FALSE),"") -> 0.5
B28: ='08_GDE_RISK_ENGINE'!A10 -> P2LBA12 BR001 | C28: ='08_GDE_RISK_ENGINE'!B10 -> Piping | D28: ='08_GDE_RISK_ENGINE'!C10 -> SAGS | E28: =IFERROR(VLOOKUP(B28,'01_ASSET_INPUT_FULL'!A:U,5,FALSE),"") -> LBA | F28: =IFERROR(VLOOKUP(B28,'01_ASSET_INPUT_FULL'!A:U,16,FALSE),"") -> Steam | G28: =IFERROR(VLOOKUP(B28,'01_ASSET_INPUT_FULL'!A:U,17,FALSE),"") -> V | H28: =IFERROR(VLOOKUP(B28,'01_ASSET_INPUT_FULL'!A:U,12,FALSE),"") -> CS | I28: ='08_GDE_RISK_ENGINE'!D10 -> CL-SAGS-LBA-STEAM-CS-V-T3_150C_PLUS | J28: ='08_GDE_RISK_ENGINE'!E10 -> 2 | K28: ='08_GDE_RISK_ENGINE'!F10 -> 5 | L28: ='08_GDE_RISK_ENGINE'!G10 -> High | M28: =IFERROR(VLOOKUP(B28,'09_INSPECTION_STRATEGY'!A:G,7,FALSE),"") -> 0.5
B29: ='08_GDE_RISK_ENGINE'!A11 -> P2LBA12 BR501 | C29: ='08_GDE_RISK_ENGINE'!B11 -> Piping | D29: ='08_GDE_RISK_ENGINE'!C11 -> SAGS | E29: =IFERROR(VLOOKUP(B29,'01_ASSET_INPUT_FULL'!A:U,5,FALSE),"") -> LBA | F29: =IFERROR(VLOOKUP(B29,'01_ASSET_INPUT_FULL'!A:U,16,FALSE),"") -> Steam | G29: =IFERROR(VLOOKUP(B29,'01_ASSET_INPUT_FULL'!A:U,17,FALSE),"") -> V | H29: =IFERROR(VLOOKUP(B29,'01_ASSET_INPUT_FULL'!A:U,12,FALSE),"") -> CS | I29: ='08_GDE_RISK_ENGINE'!D11 -> CL-SAGS-LBA-STEAM-CS-V-T3_150C_PLUS | J29: ='08_GDE_RISK_ENGINE'!E11 -> 2 | K29: ='08_GDE_RISK_ENGINE'!F11 -> 5 | L29: ='08_GDE_RISK_ENGINE'!G11 -> High | M29: =IFERROR(VLOOKUP(B29,'09_INSPECTION_STRATEGY'!A:G,7,FALSE),"") -> 0.5
B30: ='08_GDE_RISK_ENGINE'!A12 -> P2LBA12 BR011 | C30: ='08_GDE_RISK_ENGINE'!B12 -> Piping | D30: ='08_GDE_RISK_ENGINE'!C12 -> SAGS | E30: =IFERROR(VLOOKUP(B30,'01_ASSET_INPUT_FULL'!A:U,5,FALSE),"") -> LBA | F30: =IFERROR(VLOOKUP(B30,'01_ASSET_INPUT_FULL'!A:U,16,FALSE),"") -> Steam | G30: =IFERROR(VLOOKUP(B30,'01_ASSET_INPUT_FULL'!A:U,17,FALSE),"") -> V | H30: =IFERROR(VLOOKUP(B30,'01_ASSET_INPUT_FULL'!A:U,12,FALSE),"") -> CS | I30: ='08_GDE_RISK_ENGINE'!D12 -> CL-SAGS-LBA-STEAM-CS-V-T3_150C_PLUS | J30: ='08_GDE_RISK_ENGINE'!E12 -> 2 | K30: ='08_GDE_RISK_ENGINE'!F12 -> 5 | L30: ='08_GDE_RISK_ENGINE'!G12 -> High | M30: =IFERROR(VLOOKUP(B30,'09_INSPECTION_STRATEGY'!A:G,7,FALSE),"") -> 0.5
B31: ='08_GDE_RISK_ENGINE'!A13 -> P2LBA12 BR003 | C31: ='08_GDE_RISK_ENGINE'!B13 -> Piping | D31: ='08_GDE_RISK_ENGINE'!C13 -> SAGS | E31: =IFERROR(VLOOKUP(B31,'01_ASSET_INPUT_FULL'!A:U,5,FALSE),"") -> LBA | F31: =IFERROR(VLOOKUP(B31,'01_ASSET_INPUT_FULL'!A:U,16,FALSE),"") -> Steam | G31: =IFERROR(VLOOKUP(B31,'01_ASSET_INPUT_FULL'!A:U,17,FALSE),"") -> V | H31: =IFERROR(VLOOKUP(B31,'01_ASSET_INPUT_FULL'!A:U,12,FALSE),"") -> CS | I31: ='08_GDE_RISK_ENGINE'!D13 -> CL-SAGS-LBA-STEAM-CS-V-T3_150C_PLUS | J31: ='08_GDE_RISK_ENGINE'!E13 -> 2 | K31: ='08_GDE_RISK_ENGINE'!F13 -> 5 | L31: ='08_GDE_RISK_ENGINE'!G13 -> High | M31: =IFERROR(VLOOKUP(B31,'09_INSPECTION_STRATEGY'!A:G,7,FALSE),"") -> 0.5
B34: Source Documents & Basis
B35: Document
B36: Line List SAGS Area
B37: Line List Power Plant Area
B38: Equipment List
A46: =HYPERLINK("#'18_GB_CODE_MASTER'!A1","GB/KKS Code Master") -> GB/KKS Code Master

Sheet 01_ASSET_INPUT_FULL
A1: 01 Asset Input Full - Lines and Equipment
A3: Asset Tag | B3: Asset Type | C3: Source Area | D3: System | E3: Process Code | F3: Process Description | G3: KKS Level 2 | H3: Description | I3: Equipment Class | J3: Main Size (inch) | K3: Material | L3: Material Family | M3: Schedule | N3: Rating | O3: Piping Spec | P3: Fluid | Q3: Fluid State | R3: P&ID | S3: Operating Pressure (barG) | T3: Operating Temperature (degC) | U3: RBI Scope
A4: P2LBA11 BR001 | B4: Piping | C4: SAGS | D4: SAGS | E4: LBA | F4: Main Steam SAGS to Demister | G4: 11 | J4: 12 | K4: CS | L4: CS | M4: 14.27 | N4: 300 | O4: BSA6V | P4: Steam | Q4: LG | R4: PTH2-PR-LBA-PID-IKT-50002 | U4: IN
A5: P2LBA11 BR501 | B5: Piping | C5: SAGS | D5: SAGS | E5: LBA | F5: Main Steam SAGS to Demister | G5: 11 | J5: 12 | K5: CS | L5: CS | M5: STD | N5: 300 | O5: BSA6V | P5: Steam | Q5: LG | R5: PTH2-PR-LBA-PID-IKT-50001 | U5: IN
A6: P2LBA11 BR011 | B6: Piping | C6: SAGS | D6: SAGS | E6: LBA | F6: Main Steam SAGS to Demister | G6: 11 | J6: 2 | K6: CS | L6: CS | M6: S160 | N6: 300 | O6: BSA6V | P6: Steam | Q6: LG | R6: PTH2-PR-LBA-PID-IKT-50001 | U6: IN
A7: P2LBA11 BR003 | B7: Piping | C7: SAGS | D7: SAGS | E7: LBA | F7: Main Steam SAGS to Demister | G7: 11 | J7: 14 | K7: CS | L7: CS | M7: S40 | N7: 150 | O7: ASA6V | P7: Steam | Q7: LG | R7: PTH2-PR-LBA-PID-IKT-50001 | U7: IN
A8: P2LBA11 BR010 | B8: Piping | C8: SAGS | D8: SAGS | E8: LBA | F8: Main Steam SAGS to Demister | G8: 11 | J8: 3 | K8: CS | L8: CS | M8: XXS | N8: 300 | O8: BSA6V | P8: Steam | Q8: LG | R8: PTH2-PR-LBA-PID-IKT-50001 | U8: IN
A9: P2LBA11 BR301 | B9: Piping | C9: SAGS | D9: SAGS | E9: LBA | F9: Main Steam SAGS to Demister | G9: 11 | J9: 3 | K9: CS | L9: CS | M9: XXS | N9: 300 | O9: BSA6V | P9: Steam | Q9: LG | R9: PTH2-PR-LBA-PID-IKT-50001 | S9: 14.5 | T9: 199.3 | U9: IN
A10: P2LBA12 BR001 | B10: Piping | C10: SAGS | D10: SAGS | E10: LBA | F10: Main Steam SAGS to Demister | G10: 12 | J10: 12 | K10: CS | L10: CS | M10: 14.27 | N10: 300 | O10: BSA6V | P10: Steam | Q10: V | R10: PTH2-PR-LBA-PID-IKT-50002 | U10: IN
A11: P2LBA12 BR501 | B11: Piping | C11: SAGS | D11: SAGS | E11: LBA | F11: Main Steam SAGS to Demister | G11: 12 | J11: 12 | K11: CS | L11: CS | M11: 14.27 | N11: 300 | O11: BSA6V | P11: Steam | Q11: V | R11: PTH2-PR-LBA-PID-IKT-50002 | U11: IN
A12: P2LBA12 BR011 | B12: Piping | C12: SAGS | D12: SAGS | E12: LBA | F12: Main Steam SAGS to Demister | G12: 12 | J12: 2 | K12: CS | L12: CS | M12: S160 | N12: 300 | O12: BSA6V | P12: Steam | Q12: V | R12: PTH2-PR-LBA-PID-IKT-50002 | U12: IN
A13: P2LBA12 BR003 | B13: Piping | C13: SAGS | D13: SAGS | E13: LBA | F13: Main Steam SAGS to Demister | G13: 12 | J13: 14 | K13: CS | L13: CS | M13: S40 | N13: 150 | O13: ASA6V | P13: Steam | Q13: V | R13: PTH2-PR-LBA-PID-IKT-50002 | U13: IN
A14: P2LBA12 BR010 | B14: Piping | C14: SAGS | D14: SAGS | E14: LBA | F14: Main Steam SAGS to Demister | G14: 12 | J14: 3 | K14: CS | L14: CS | M14: XXS | N14: 300 | O14: BSA6V | P14: Steam | Q14: V | R14: PTH2-PR-LBA-PID-IKT-50002 | U14: IN
A15: P2LBA12 BR301 | B15: Piping | C15: SAGS | D15: SAGS | E15: LBA | F15: Main Steam SAGS to Demister | G15: 12 | J15: 3 | K15: CS | L15: CS | M15: XXS | N15: 300 | O15: BSA6V | P15: Steam | Q15: V | R15: PTH2-PR-LBA-PID-IKT-50002 | S15: 10.4 | T15: 185.1 | U15: IN
A16: P2LBA13 BR001 | B16: Piping | C16: SAGS | D16: SAGS | E16: LBA | F16: Main Steam SAGS to Demister | G16: 13 | J16: 12 | K16: CS | L16: CS | M16: 14.27 | N16: 300 | O16: BSA6V | P16: Steam | Q16: V | R16: PTH2-PR-LBA-PID-IKT-50002 | U16: IN
A17: P2LBA13 BR501 | B17: Piping | C17: SAGS | D17: SAGS | E17: LBA | F17: Main Steam SAGS to Demister | G17: 13 | J17: 12 | K17: CS | L17: CS | M17: 14.27 | N17: 300 | O17: BSA6V | P17: Steam | Q17: V | R17: PTH2-PR-LBA-PID-IKT-50002 | U17: IN
A18: P2LBA13 BR011 | B18: Piping | C18: SAGS | D18: SAGS | E18: LBA | F18: Main Steam SAGS to Demister | G18: 13 | J18: 2 | K18: CS | L18: CS | M18: S160 | N18: 300 | O18: BSA6V | P18: Steam | Q18: V | R18: PTH2-PR-LBA-PID-IKT-50002 | U18: IN
A19: P2LBA13 BR003 | B19: Piping | C19: SAGS | D19: SAGS | E19: LBA | F19: Main Steam SAGS to Demister | G19: 13 | J19: 14 | K19: CS | L19: CS | M19: S40 | N19: 150 | O19: ASA6V | P19: Steam | Q19: V | R19: PTH2-PR-LBA-PID-IKT-50002 | U19: IN
A20: P2LBA13 BR010 | B20: Piping | C20: SAGS | D20: SAGS | E20: LBA | F20: Main Steam SAGS to Demister | G20: 13 | J20: 3 | K20: CS | L20: CS | M20: XXS | N20: 300 | O20: BSA6V | P20: Steam | Q20: V | R20: PTH2-PR-LBA-PID-IKT-50002 | U20: IN
A21: P2LBA13 BR301 | B21: Piping | C21: SAGS | D21: SAGS | E21: LBA | F21: Main Steam SAGS to Demister | G21: 13 | J21: 3 | K21: CS | L21: CS | M21: XXS | N21: 300 | O21: BSA6V | P21: Steam | Q21: V | R21: PTH2-PR-LBA-PID-IKT-50002 | S21: 9.6 | T21: 181.8 | U21: IN
A22: P2LBA10 BR002 | B22: Piping | C22: SAGS | D22: SAGS | E22: LBA | F22: Main Steam SAGS to Demister | G22: 10 | J22: 20 | K22: CS | L22: CS | M22: XS | N22: 150 | O22: ASA6V | P22: Steam | Q22: V | R22: PTH2-PR-LBA-PID-IKT-50002 | U22: IN
A23: P2LBA14 BR001 | B23: Piping | C23: SAGS | D23: SAGS | E23: LBA | F23: Main Steam SAGS to Demister | G23: 14 | J23: 12 | K23: CS | L23: CS | M23: 14.27 | N23: 300 | O23: BSA6V | P23: Steam | Q23: V | R23: PTH2-PR-LBA-PID-IKT-50003 | U23: IN
A24: P2LBA14 BR501 | B24: Piping | C24: SAGS | D24: SAGS | E24: LBA | F24: Main Steam SAGS to Demister | G24: 14 | J24: 12 | K24: CS | L24: CS | M24: 14.27 | N24: 300 | O24: BSA6V | P24: Steam | Q24: V | R24: PTH2-PR-LBA-PID-IKT-50003 | U24: IN
A25: P2LBA14 BR003 | B25: Piping | C25: SAGS | D25: SAGS | E25: LBA | F25: Main Steam SAGS to Demister | G25: 14 | J25: 14 | K25: CS | L25: CS | M25: S40 | N25: 150 | O25: ASA6V | P25: Steam | Q25: V | R25: PTH2-PR-LBA-PID-IKT-50003 | U25: IN
A26: P2LBA14 BR011 | B26: Piping | C26: SAGS | D26: SAGS | E26: LBA | F26: Main Steam SAGS to Demister | G26: 14 | J26: 2 | K26: CS | L26: CS | M26: S160 | N26: 300 | O26: BSA6V | P26: Steam | Q26: V | R26: PTH2-PR-LBA-PID-IKT-50003 | U26: IN
A27: P2LBA14 BR010 | B27: Piping | C27: SAGS | D27: SAGS | E27: LBA | F27: Main Steam SAGS to Demister | G27: 14 | J27: 3 | K27: CS | L27: CS | M27: XXS | N27: 300 | O27: BSA6V | P27: Steam | Q27: V | R27: PTH2-PR-LBA-PID-IKT-50003 | U27: IN
A28: P2LBA14 BR301 | B28: Piping | C28: SAGS | D28: SAGS | E28: LBA | F28: Main Steam SAGS to Demister | G28: 14 | J28: 3 | K28: CS | L28: CS | M28: XXS | N28: 300 | O28: BSA6V | P28: Steam | Q28: V | R28: PTH2-PR-LBA-PID-IKT-50003 | S28: 8.5 | T28: 176.9 | U28: IN
A29: P2LBA21 BR001 | B29: Piping | C29: SAGS | D29: SAGS | E29: LBA | F29: Main Steam SAGS to Demister | G29: 21 | J29: 12 | K29: CS | L29: CS | M29: 14.27 | N29: 300 | O29: BSA6V | P29: Steam | Q29: V | R29: PTH2-PR-LBA-PID-IKT-50004 | U29: IN
A30: P2LBA21 BR501 | B30: Piping | C30: SAGS | D30: SAGS | E30: LBA | F30: Main Steam SAGS to Demister | G30: 21 | J30: 12 | K30: CS | L30: CS | M30: 14.27 | N30: 300 | O30: BSA6V | P30: Steam | Q30: V | R30: PTH2-PR-LBA-PID-IKT-50004 | U30: IN
A31: P2LBA21 BR010 | B31: Piping | C31: SAGS | D31: SAGS | E31: LBA | F31: Main Steam SAGS to Demister | G31: 21 | J31: 3 | K31: CS | L31: CS | M31: XXS | N31: 300 | O31: BSA6V | P31: Steam | Q31: V | R31: PTH2-PR-LBA-PID-IKT-50004 | U31: IN
A32: P2LBA21 BR301 | B32: Piping | C32: SAGS | D32: SAGS | E32: LBA | F32: Main Steam SAGS to Demister | G32: 21 | J32: 3 | K32: CS | L32: CS | M32: XXS | N32: 300 | O32: BSA6V | P32: Steam | Q32: V | R32: PTH2-PR-LBA-PID-IKT-50004 | S32: 15.4 | T32: 201.9 | U32: IN
A33: P2LBA22 BR001 | B33: Piping | C33: SAGS | D33: SAGS | E33: LBA | F33: Main Steam SAGS to Demister | G33: 22 | J33: 12 | K33: CS | L33: CS | M33: 14.27 | N33: 300 | O33: BSA6V | P33: Steam | Q33: V | R33: PTH2-PR-LBA-PID-IKT-50004 | U33: IN
A34: P2LBA22 BR501 | B34: Piping | C34: SAGS | D34: SAGS | E34: LBA | F34: Main Steam SAGS to Demister | G34: 22 | J34: 12 | K34: CS | L34: CS | M34: 14.27 | N34: 300 | O34: BSA6V | P34: Steam | Q34: V | R34: PTH2-PR-LBA-PID-IKT-50004 | U34: IN
A35: P2LBA22 BR011 | B35: Piping | C35: SAGS | D35: SAGS | E35: LBA | F35: Main Steam SAGS to Demister | G35: 22 | J35: 2 | K35: CS | L35: CS | M35: S160 | N35: 300 | O35: BSA6V | P35: Steam | Q35: V | R35: PTH2-PR-LBA-PID-IKT-50004 | U35: IN
A36: P2LBA22 BR010 | B36: Piping | C36: SAGS | D36: SAGS | E36: LBA | F36: Main Steam SAGS to Demister | G36: 22 | J36: 3 | K36: CS | L36: CS | M36: XXS | N36: 300 | O36: BSA6V | P36: Steam | Q36: V | R36: PTH2-PR-LBA-PID-IKT-50004 | U36: IN
A37: P2LBA22 BR301 | B37: Piping | C37: SAGS | D37: SAGS | E37: LBA | F37: Main Steam SAGS to Demister | G37: 22 | J37: 3 | K37: CS | L37: CS | M37: XXS | N37: 300 | O37: BSA6V | P37: Steam | Q37: V | R37: PTH2-PR-LBA-PID-IKT-50004 | S37: 18.2 | T37: 209.9 | U37: IN
A38: P2LBA25 BR001 | B38: Piping | C38: SAGS | D38: SAGS | E38: LBA | F38: Main Steam SAGS to Demister | G38: 25 | J38: 12 | K38: CS | L38: CS | M38: 14.27 | N38: 300 | O38: BSA6V | P38: Steam | Q38: V | R38: PTH2-PR-LBA-PID-IKT-50005 | U38: IN
A39: P2LBA25 BR501 | B39: Piping | C39: SAGS | D39: SAGS | E39: LBA | F39: Main Steam SAGS to Demister | G39: 25 | J39: 12 | K39: CS | L39: CS | M39: 14.27 | N39: 300 | O39: BSA6V | P39: Steam | Q39: V | R39: PTH2-PR-LBA-PID-IKT-50005 | U39: IN
A40: P2LBA25 BR003 | B40: Piping | C40: SAGS | D40: SAGS | E40: LBA | F40: Main Steam SAGS to Demister | G40: 25 | J40: 14 | K40: CS | L40: CS | M40: S40 | N40: 150 | O40: ASA6V | P40: Steam | Q40: V | R40: PTH2-PR-LBA-PID-IKT-50005 | U40: IN
A41: P2LBA25 BR011 | B41: Piping | C41: SAGS | D41: SAGS | E41: LBA | F41: Main Steam SAGS to Demister | G41: 25 | J41: 2 | K41: CS | L41: CS | M41: S160 | N41: 300 | O41: BSA6V | P41: Steam | Q41: V | R41: PTH2-PR-LBA-PID-IKT-50005 | U41: IN
...

Sheet 02_ASSET_HIERARCHY_FULL
A1: 02 Asset Hierarchy Full
A3: Plant | B3: Area | C3: System | D3: Process Code | E3: Corrosion Loop / Equipment Model | F3: Asset Tag | G3: Asset Type | H3: ECA Category | I3: RBI Scope
A4: Patuha Unit-2 | B4: SAGS | C4: SAGS | D4: LBA | E4: CL-SAGS-LBA-STEAM-CS-LG-T3_150C_PLUS | F4: P2LBA11 BR001 | G4: Piping | H4: C1 | I4: IN
A5: Patuha Unit-2 | B5: SAGS | C5: SAGS | D5: LBA | E5: CL-SAGS-LBA-STEAM-CS-LG-T3_150C_PLUS | F5: P2LBA11 BR501 | G5: Piping | H5: C1 | I5: IN
A6: Patuha Unit-2 | B6: SAGS | C6: SAGS | D6: LBA | E6: CL-SAGS-LBA-STEAM-CS-LG-T3_150C_PLUS | F6: P2LBA11 BR011 | G6: Piping | H6: C1 | I6: IN
A7: Patuha Unit-2 | B7: SAGS | C7: SAGS | D7: LBA | E7: CL-SAGS-LBA-STEAM-CS-LG-T3_150C_PLUS | F7: P2LBA11 BR003 | G7: Piping | H7: C1 | I7: IN
A8: Patuha Unit-2 | B8: SAGS | C8: SAGS | D8: LBA | E8: CL-SAGS-LBA-STEAM-CS-LG-T3_150C_PLUS | F8: P2LBA11 BR010 | G8: Piping | H8: C1 | I8: IN
A9: Patuha Unit-2 | B9: SAGS | C9: SAGS | D9: LBA | E9: CL-SAGS-LBA-STEAM-CS-LG-T3_150C_PLUS | F9: P2LBA11 BR301 | G9: Piping | H9: C1 | I9: IN
A10: Patuha Unit-2 | B10: SAGS | C10: SAGS | D10: LBA | E10: CL-SAGS-LBA-STEAM-CS-V-T3_150C_PLUS | F10: P2LBA12 BR001 | G10: Piping | H10: C1 | I10: IN
A11: Patuha Unit-2 | B11: SAGS | C11: SAGS | D11: LBA | E11: CL-SAGS-LBA-STEAM-CS-V-T3_150C_PLUS | F11: P2LBA12 BR501 | G11: Piping | H11: C1 | I11: IN
A12: Patuha Unit-2 | B12: SAGS | C12: SAGS | D12: LBA | E12: CL-SAGS-LBA-STEAM-CS-V-T3_150C_PLUS | F12: P2LBA12 BR011 | G12: Piping | H12: C1 | I12: IN
A13: Patuha Unit-2 | B13: SAGS | C13: SAGS | D13: LBA | E13: CL-SAGS-LBA-STEAM-CS-V-T3_150C_PLUS | F13: P2LBA12 BR003 | G13: Piping | H13: C1 | I13: IN
A14: Patuha Unit-2 | B14: SAGS | C14: SAGS | D14: LBA | E14: CL-SAGS-LBA-STEAM-CS-V-T3_150C_PLUS | F14: P2LBA12 BR010 | G14: Piping | H14: C1 | I14: IN
... A416: Patuha Unit-2 | B416: Equipment List | C416: Equipment | D416: SGA | E416: EQ-EQUIP-SGA-STATICEQUIPMENT | F416: PTH2SGA15 BB001 | G416: Equipment | H416: C3 | I416: LIMITED

Sheet 03_ECA_FULL
A1: 03 ECA Full - Scope Gate
A3: Asset Tag | B3: Asset Type | C3: System | D3: Process Code | E3: Production Impact Score | F3: Safety/Environment Score | G3: Maintainability Score | H3: Final ECA Score | I3: ECA Category | J3: RBI Scope | K3: ECA Basis
A4: P2LBA11 BR001 | B4: Piping | C4: SAGS | D4: LBA | E4: 5 | F4: 3 | G4: 2 | H4: 9 | I4: C1 | J4: IN | K4: C1/C2 included in RBI; C3 routine/non-assessed. Non-metallic piping set to LIMITED RBI.
A5: P2LBA11 BR501 | B5: Piping | C5: SAGS | D5: LBA | E5: 5 | F5: 3 | G5: 2 | H5: 9 | I5: C1 | J5: IN | K5: C1/C2 included in RBI; C3 routine/non-assessed. Non-metallic piping set to LIMITED RBI.
A6: P2LBA11 BR011 | B6: Piping | C6: SAGS | D6: LBA | E6: 5 | F6: 3 | G6: 2 | H6: 9 | I6: C1 | J6: IN | K6: C1/C2 included in RBI; C3 routine/non-assessed. Non-metallic piping set to LIMITED RBI.
A7: P2LBA11 BR003 | B7: Piping | C7: SAGS | D7: LBA | E7: 5 | F7: 3 | G7: 2 | H7: 9 | I7: C1 | J7: IN | K7: C1/C2 included in RBI; C3 routine/non-assessed. Non-metallic piping set to LIMITED RBI.
A8: P2LBA11 BR010 | B8: Piping | C8: SAGS | D8: LBA | E8: 5 | F8: 3 | G8: 2 | H8: 9 | I8: C1 | J8: IN | K8: C1/C2 included in RBI; C3 routine/non-assessed. Non-metallic piping set to LIMITED RBI.
A9: P2LBA11 BR301 | B9: Piping | C9: SAGS | D9: LBA | E9: 5 | F9: 3 | G9: 2 | H9: 9 | I9: C1 | J9: IN | K9: C1/C2 included in RBI; C3 routine/non-assessed. Non-metallic piping set to LIMITED RBI.
A10: P2LBA12 BR001 | B10: Piping | C10: SAGS | D10: LBA | E10: 5 | F10: 3 | G10: 2 | H10: 9 | I10: C1 | J10: IN | K10: C1/C2 included in RBI; C3 routine/non-assessed. Non-metallic piping set to LIMITED RBI.
A11: P2LBA12 BR501 | B11: Piping | C11: SAGS | D11: LBA | E11: 5 | F11: 3 | G11: 2 | H11: 9 | I11: C1 | J11: IN | K11: C1/C2 included in RBI; C3 routine/non-assessed. Non-metallic piping set to LIMITED RBI.
A12: P2LBA12 BR011 | B12: Piping | C12: SAGS | D12: LBA | E12: 5 | F12: 3 | G12: 2 | H12: 9 | I12: C1 | J12: IN | K12: C1/C2 included in RBI; C3 routine/non-assessed. Non-metallic piping set to LIMITED RBI.
A13: P2LBA12 BR003 | B13: Piping | C13: SAGS | D13: LBA | E13: 5 | F13: 3 | G13: 2 | H13: 9 | I13: C1 | J13: IN | K13: C1/C2 included in RBI; C3 routine/non-assessed. Non-metallic piping set to LIMITED RBI.
A14: P2LBA12 BR010 | B14: Piping | C14: SAGS | D14: LBA | E14: 5 | F14: 3 | G14: 2 | H14: 9 | I14: C1 | J14: IN | K14: C1/C2 included in RBI; C3 routine/non-assessed. Non-metallic piping set to LIMITED RBI.
A15: P2LBA12 BR301 | B15: Piping | C15: SAGS | D15: LBA | E15: 5 | F15: 3 | G15: 2 | H15: 9 | I15: C1 | J15: IN | K15: C1/C2 included in RBI; C3 routine/non-assessed. Non-metallic piping set to LIMITED RBI.
... A416: PTH2SGA15 BB001 | B416: Equipment | C416: Equipment | D416: SGA | E416: 1 | F416: 2 | G416: 3 | H416: 7 | I416: C3 | J416: LIMITED | K416: C1/C2 included in RBI; C3 routine/non-assessed. Non-metallic piping set to LIMITED RBI.

Sheet 04_CORROSION_LOOP_MODEL
A1: 04 Corrosion Loop / Equipment Model
A3: Corrosion Loop ID | B3: Asset Count | C3: Asset Type Mix | D3: System | E3: Process Code | F3: Fluid | G3: Fluid State | H3: Material Family | I3: Dominant Damage Mechanisms | J3: Avg PoF | K3: Max CoF | L3: Max Risk Level | M3: Recommended Inspection Method | N3: Recommended Interval (yr)
A4: CL-SAGS-LBA-STEAM-CS-LG-T3_150C_PLUS | B4: 17 | C4: Piping | D4: SAGS | E4: LBA | F4: Steam | G4: LG | H4: CS | I4: CO2 corrosion; Erosion-corrosion / FAC; CUI | J4: 4 | K4: 5 | L4: Extreme High | M4: UT Scan + VT | N4: 0.5
A5: EQ-POWER-MAJ-STATICEQUIPMENT | B5: 3 | C5: Equipment | D5: Power Block | E5: MAJ | H5: SS316L | I5: General external corrosion; CUI if insulated | J5: 3 | K5: 5 | L5: Extreme High | M5: VT + UT thickness / component inspection | N5: 0.5
A6: CL-SAGS-LBA-CONDENSATE-CS-L-T1_BELOW_80C | B6: 2 | C6: Piping | D6: SAGS | E6: LBA | F6: Condensate | G6: L | H6: CS | I6: CO2 condensate corrosion; Oxygen corrosion; MIC / under-deposit | J6: 4 | K6: 4 | L6: Extreme High | M6: UT Scan + VT | N6: 0.5
A7: CL-POWER-MAW-CONDENSATESTEAM-CS-L-T1_BELOW_80C | B7: 1 | C7: Piping | D7: Power Block | E7: MAW | F7: Condensate Steam | G7: L | H7: CS | I7: CO2 condensate corrosion; Oxygen corrosion; MIC / under-deposit | J7: 4 | K7: 4 | L7: Extreme High | M7: UT Scan + VT | N7: 0.5
A8: EQ-SAGS-LBJ-STATICEQUIPMENT | B8: 1 | C8: Equipment | D8: SAGS | E8: LBJ | H8: SS316L | I8: General external corrosion; CUI if insulated | J8: 3 | K8: 5 | L8: Extreme High | M8: VT + UT thickness / component inspection | N8: 0.5
A9: CL-SAGS-LBA-STEAM-CS-V-T3_150C_PLUS | B9: 48 | C9: Piping | D9: SAGS | E9: LBA | F9: Steam | G9: V | H9: CS | I9: CUI; Atmospheric corrosion; Erosion (localized) | J9: 2 | K9: 5 | L9: High | M9: VT + CUI screening | N9: 0.5
A10: CL-BOPUT-PCB-COOLINGWATER--L-T1_BELOW_80C | B10: 29 | C10: Piping | D10: BOP/Utility | E10: PCB | F10: Cooling Water | G10: L | I10: Cooling water corrosion; MIC; Oxygen corrosion | J10: 2 | K10: 3 | L10: High | M10: VT / Sampling | N10: 0.5
A11: CL-POWER-MAJ-NCG-SS316L-V-T0_UNKNOWN | B11: 22 | C11: Piping | D11: Power Block | E11: MAJ | F11: NCG | G11: V | H11: SS316L | I11: H2S / sour corrosion; CLSCC (if chloride + SS); Atmospheric/CUI | J11: 2 | K11: 4 | L11: High | M11: VT + CUI screening | N11: 0.5
A12: CL-BOPUT-PAB-COOLINGWATER-SS316L-L-T1_BELOW_80C | B12: 21 | C12: Piping | D12: BOP/Utility | E12: PAB | F12: Cooling Water | G12: L | H12: SS316L | I12: Cooling water corrosion; MIC; Oxygen corrosion | J12: 2 | K12: 3 | L12: High | M12: VT / Sampling | N12: 0.5
A13: CL-BOPUT-LCA-CONDENSATE-CS-L-T1_BELOW_80C | B13: 20 | C13: Piping | D13: BOP/Utility | E13: LCA | F13: Condensate | G13: L | H13: CS | I13: CO2 condensate corrosion; Oxygen corrosion; MIC / under-deposit | J13: 4 | K13: 2 | L13: High | M13: UT Scan + VT | N13: 0.5
A14: CL-POWER-MAJ-COOLINGWATER-SS316L-L-T1_BELOW_80C | B14: 8 | C14: Piping | D14: Power Block | E14: MAJ | F14: Cooling Water | G14: L | H14: SS316L | I14: Cooling water corrosion; MIC; Oxygen corrosion | J14: 2 | K14: 4 | L14: High | M14: VT / Sampling | N14: 0.5
A15: CL-BOPUT-PCB-COOLINGWATER-FRP-L-T1_BELOW_80C | B15: 8 | C15: Piping | D15: BOP/Utility | E15: PCB | F15: Cooling Water | G15: L | H15: FRP | I15: Non-metallic degradation / erosion; Joint/leakage; Fouling | J15: 2 | K15: 3 | L15: High | M15: VT / Sampling | N15: 0.5
A16: CL-BOPUT-QCH--CS--T0_UNKNOWN | B16: 8 | C16: Piping | D16: BOP/Utility | E16: QCH | H16: CS | I16: General external corrosion; CUI if insulated | J16: 3 | K16: 2 | L16: High | M16: VT + CUI screening | N16: 0.5
A17: CL-BOPUT-PAB-CONDENSATE--L-T1_BELOW_80C | B17: 7 | C17: Piping | D17: BOP/Utility | E17: PAB | F17: Condensate | G17: L | I17: CO2 condensate corrosion; Oxygen corrosion; MIC / under-deposit | J17: 2 | K17: 3 | L17: High | M17: VT / Sampling | N17: 0.5
A18: CL-SAGS-LBA-STEAM-CS-V-T1_BELOW_80C | B18: 6 | C18: Piping | D18: SAGS | E18: LBA | F18: Steam | G18: V | H18: CS | I18: CUI; Atmospheric corrosion; Erosion (localized) | J18: 2 | K18: 5 | L18: High | M18: VT + CUI screening | N18: 0.5
A19: CL-BOPUT-PAD-COOLINGWATER--L-T1_BELOW_80C | B19: 6 | C19: Piping | D19: BOP/Utility | E19: PAD | F19: Cooling Water | G19: L | I19: Cooling water corrosion; MIC; Oxygen corrosion | J19: 2 | K19: 3 | L19: High | M19: VT / Sampling | N19: 0.5
A20: EQ-POWER-MAJ-EQUIPMENT | B20: 6 | C20: Equipment | D20: Power Block | E20: MAJ | I20: General external corrosion; CUI if insulated | J20: 2 | K20: 4 | L20: High | M20: Package inspection / function test / VT | N20: 0.5
A21: CL-SAGS-LBF-CONDENSATE-CS-L-T1_BELOW_80C | B21: 4 | C21: Piping | D21: SAGS | E21: LBF | F21: Condensate | G21: L | H21: CS | I21: CO2 condensate corrosion; Oxygen corrosion; MIC / under-deposit | J21: 4 | K21: 2 | L21: High | M21: UT Scan + VT | N21: 0.5
A22: CL-BOPUT-PAD-COOLINGWATER-SS316L-L-T1_BELOW_80C | B22: 4 | C22: Piping | D22: BOP/Utility | E22: PAD | F22: Cooling Water | G22: L | H22: SS316L | I22: Cooling water corrosion; MIC; Oxygen corrosion | J22: 2 | K22: 3 | L22: High | M22: VT / Sampling | N22: 0.5
A23: EQ-POWER-MAV-EQUIPMENT | B23: 4 | C23: Equipment | D23: Power Block | E23: MAV | I23: General external corrosion; CUI if insulated | J23: 2 | K23: 4 | L23: High | M23: Package inspection / function test / VT | N23: 0.5
A24: CL-SAGS-LCM-CONDENSATE-CS-L-T1_BELOW_80C | B24: 3 | C24: Piping | D24: SAGS | E24: LCM | F24: Condensate | G24: L | H24: CS | I24: CO2 condensate corrosion; Oxygen corrosion; MIC / under-deposit | J24: 4 | K24: 2 | L24: High | M24: UT Scan + VT | N24: 0.5
A25: CL-POWER-LBG-STEAM-CS-V-T3_150C_PLUS | B25: 3 | C25: Piping | D25: Power Block | E25: LBG | F25: Steam | G25: V | H25: CS | I25: CUI; Atmospheric corrosion; Erosion (localized) | J25: 2 | K25: 4 | L25: High | M25: VT + CUI screening | N25: 0.5
A26: CL-BOPUT-PAE-COOLINGWATER-SS316L-L-T1_BELOW_80C | B26: 3 | C26: Piping | D26: BOP/Utility | E26: PAE | F26: Cooling Water | G26: L | H26: SS316L | I26: Cooling water corrosion; MIC; Oxygen corrosion | J26: 2 | K26: 3 | L26: High | M26: VT / Sampling | N26: 0.5
A27: CL-BOPUT-PCB-SEALWATER-SS316L-L-T1_BELOW_80C | B27: 3 | C27: Piping | D27: BOP/Utility | E27: PCB | F27: Seal Water | G27: L | H27: SS316L | I27: Oxygen corrosion; MIC | J27: 2 | K27: 3 | L27: High | M27: VT / Sampling | N27: 0.5
A28: EQ-POWER-MAV-STATICEQUIPMENT | B28: 3 | C28: Equipment | D28: Power Block | E28: MAV | H28: SS316L | I28: General external corrosion; CUI if insulated | J28: 3 | K28: 4 | L28: High | M28: VT + UT thickness / component inspection | N28: 0.5
A29: CL-BOPUT-PAB-STEAMWASH-SS316L-L-T0_UNKNOWN | B29: 2 | C29: Piping | D29: BOP/Utility | E29: PAB | F29: Steam Wash | G29: L | H29: SS316L | I29: CO2 condensate corrosion; Oxygen corrosion; MIC / under-deposit | J29: 2 | K29: 3 | L29: High | M29: VT / Sampling | N29: 0.5
A30: CL-BOPUT-PAB-CONDENSATE-SS316L-L-T1_BELOW_80C | B30: 2 | C30: Piping | D30: BOP/Utility | E30: PAB | F30: Condensate | G30: L | H30: SS316L | I30: CO2 condensate corrosion; Oxygen corrosion; MIC / under-deposit | J30: 2 | K30: 3 | L30: High | M30: VT / Sampling | N30: 0.5
A31: CL-BOPUT-PCB-COOLINGWATER-SS316L-L-T1_BELOW_80C | B31: 2 | C31: Piping | D31: BOP/Utility | E31: PCB | F31: Cooling Water | G31: L | H31: SS316L | I31: Cooling water corrosion; MIC; Oxygen corrosion | J31: 2 | K31: 3 | L31: High | M31: VT / Sampling | N31: 0.5
A32: CL-BOPUT-QCH--CS--T1_BELOW_80C | B32: 2 | C32: Piping | D32: BOP/Utility | E32: QCH | H32: CS | I32: General external corrosion; CUI if insulated | J32: 3 | K32: 2 | L32: High | M32: VT + CUI screening | N32: 0.5
A33: EQ-SAGS-LBF-CIVILSTATIC | B33: 2 | C33: Equipment | D33: SAGS | E33: LBF | H33: CARBON STEEL | I33: General external corrosion; CUI if insulated | J33: 3 | K33: 4 | L33: High | M33: VT + UT thickness / component inspection | N33: 0.5
A34: EQ-BOPUT-QEA-STATICEQUIPMENT | B34: 2 | C34: Equipment | D34: BOP/Utility | E34: QEA | H34: SS304L | I34: General external corrosion; CUI if insulated | J34: 3 | K34: 4 | L34: High | M34: VT + UT thickness / component inspection | N34: 0.5
A35: CL-POWER-LBG-STEAM-CS-V-T1_BELOW_80C | B35: 1 | C35: Piping | D35: Power Block | E35: LBG | F35: Steam | G35: V | H35: CS | I35: CUI; Atmospheric corrosion; Erosion (localized) | J35: 2 | K35: 4 | L35: High | M35: VT + CUI screening | N35: 0.5
A36: CL-SAGS-LBA-STEAM--V-T3_150C_PLUS | B36: 1 | C36: Piping | D36: SAGS | E36: LBA | F36: Steam | G36: V | I36: CUI; Atmospheric corrosion; Erosion (localized) | J36: 2 | K36: 5 | L36: High | M36: VT + CUI screening | N36: 0.5
A37: CL-POWER-MAW-GLANDSTEAM-SS316L-V-T2_80_150C | B37: 1 | C37: Piping | D37: Power Block | E37: MAW | F37: Gland Steam | G37: V | H37: SS316L | I37: CUI; Atmospheric corrosion; Erosion (localized) | J37: 2 | K37: 4 | L37: High | M37: VT + CUI screening | N37: 0.5
A38: CL-BOPUT-PAB-SPRAYWATER-SS316L-L-T0_UNKNOWN | B38: 1 | C38: Piping | D38: BOP/Utility | E38: PAB | F38: Spray Water | G38: L | H38: SS316L | I38: Oxygen corrosion; MIC | J38: 2 | K38: 3 | L38: High | M38: VT / Sampling | N38: 0.5
A39: CL-POWER-MAW-GLANDSTEAM-SS316L-L-T1_BELOW_80C | B39: 1 | C39: Piping | D39: Power Block | E39: MAW | F39: Gland Steam | G39: L | H39: SS316L | I39: General external corrosion; CUI if insulated | J39: 2 | K39: 4 | L39: High | M39: VT + CUI screening | N39: 0.5
A40: CL-POWER-MAJ-NCG-SS316L-V-T1_BELOW_80C | B40: 1 | C40: Piping | D40: Power Block | E40: MAJ | F40: NCG | G40: V | H40: SS316L | I40: H2S / sour corrosion; CLSCC (if chloride + SS); Atmospheric/CUI | J40: 2 | K40: 4 | L40: High | M40: VT + CUI screening | N40: 0.5
A41: CL-POWER-MAJ-COOLINGWATER--L-T1_BELOW_80C | B41: 1 | C41: Piping | D41: Power Block | E41: MAJ | F41: Cooling Water | G41: L | I41: Cooling water corrosion; MIC; Oxygen corrosion | J41: 2 | K41: 4 | L41: High | M41: VT / Sampling | N41: 0.5
...

Sheet 05_DAMAGE_MECHANISM_MODEL
A1: 05 Damage Mechanism Model
A3: Corrosion Loop ID | B3: System | C3: Fluid | D3: Phase | E3: Material | F3: Dominant DM | G3: PoF Driver | H3: Inspection Effectiveness Need | I3: Comment
A4: CL-SAGS-LBA-STEAM-CS-LG-T3_150C_PLUS | B4: SAGS | C4: Steam | D4: LG | E4: CS | F4: CO2 corrosion; Erosion-corrosion / FAC; CUI | G4: phase + material + fluid service + temperature band | H4: method must detect listed DM | I4: Preliminary DM; validate against P&ID, chemistry and baseline inspection.
A5: EQ-POWER-MAJ-STATICEQUIPMENT | B5: Power Block | E5: SS316L | F5: General external corrosion; CUI if insulated | G5: phase + material + fluid service + temperature band | H5: method must detect listed DM | I5: Preliminary DM; validate against P&ID, chemistry and baseline inspection.
A6: CL-SAGS-LBA-CONDENSATE-CS-L-T1_BELOW_80C | B6: SAGS | C6: Condensate | D6: L | E6: CS | F6: CO2 condensate corrosion; Oxygen corrosion; MIC / under-deposit | G6: phase + material + fluid service + temperature band | H6: method must detect listed DM | I6: Preliminary DM; validate against P&ID, chemistry and baseline inspection.
A7: CL-POWER-MAW-CONDENSATESTEAM-CS-L-T1_BELOW_80C | B7: Power Block | C7: Condensate Steam | D7: L | E7: CS | F7: CO2 condensate corrosion; Oxygen corrosion; MIC / under-deposit | G7: phase + material + fluid service + temperature band | H7: method must detect listed DM | I7: Preliminary DM; validate against P&ID, chemistry and baseline inspection.
A8: EQ-SAGS-LBJ-STATICEQUIPMENT | B8: SAGS | E8: SS316L | F8: General external corrosion; CUI if insulated | G8: phase + material + fluid service + temperature band | H8: method must detect listed DM | I8: Preliminary DM; validate against P&ID, chemistry and baseline inspection.
A9: CL-SAGS-LBA-STEAM-CS-V-T3_150C_PLUS | B9: SAGS | C9: Steam | D9: V | E9: CS | F9: CUI; Atmospheric corrosion; Erosion (localized) | G9: phase + material + fluid service + temperature band | H9: method must detect listed DM | I9: Preliminary DM; validate against P&ID, chemistry and baseline inspection.
A10: CL-BOPUT-PCB-COOLINGWATER--L-T1_BELOW_80C | B10: BOP/Utility | C10: Cooling Water | D10: L | F10: Cooling water corrosion; MIC; Oxygen corrosion | G10: phase + material + fluid service + temperature band | H10: method must detect listed DM | I10: Preliminary DM; validate against P&ID, chemistry and baseline inspection.
A11: CL-POWER-MAJ-NCG-SS316L-V-T0_UNKNOWN | B11: Power Block | C11: NCG | D11: V | E11: SS316L | F11: H2S / sour corrosion; CLSCC (if chloride + SS); Atmospheric/CUI | G11: phase + material + fluid service + temperature band | H11: method must detect listed DM | I11: Preliminary DM; validate against P&ID, chemistry and baseline inspection.
A12: CL-BOPUT-PAB-COOLINGWATER-SS316L-L-T1_BELOW_80C | B12: BOP/Utility | C12: Cooling Water | D12: L | E12: SS316L | F12: Cooling water corrosion; MIC; Oxygen corrosion | G12: phase + material + fluid service + temperature band | H12: method must detect listed DM | I12: Preliminary DM; validate against P&ID, chemistry and baseline inspection.
A13: CL-BOPUT-LCA-CONDENSATE-CS-L-T1_BELOW_80C | B13: BOP/Utility | C13: Condensate | D13: L | E13: CS | F13: CO2 condensate corrosion; Oxygen corrosion; MIC / under-deposit | G13: phase + material + fluid service + temperature band | H13: method must detect listed DM | I13: Preliminary DM; validate against P&ID, chemistry and baseline inspection.
A14: CL-POWER-MAJ-COOLINGWATER-SS316L-L-T1_BELOW_80C | B14: Power Block | C14: Cooling Water | D14: L | E14: SS316L | F14: Cooling water corrosion; MIC; Oxygen corrosion | G14: phase + material + fluid service + temperature band | H14: method must detect listed DM | I14: Preliminary DM; validate against P&ID, chemistry and baseline inspection.
A15: CL-BOPUT-PCB-COOLINGWATER-FRP-L-T1_BELOW_80C | B15: BOP/Utility | C15: Cooling Water | D15: L | E15: FRP | F15: Non-metallic degradation / erosion; Joint/leakage; Fouling | G15: phase + material + fluid service + temperature band | H15: method must detect listed DM | I15: Preliminary DM; validate against P&ID, chemistry and baseline inspection.
A16: CL-BOPUT-QCH--CS--T0_UNKNOWN | B16: BOP/Utility | E16: CS | F16: General external corrosion; CUI if insulated | G16: phase + material + fluid service + temperature band | H16: method must detect listed DM | I16: Preliminary DM; validate against P&ID, chemistry and baseline inspection.
A17: CL-BOPUT-PAB-CONDENSATE--L-T1_BELOW_80C | B17: BOP/Utility | C17: Condensate | D17: L | F17: CO2 condensate corrosion; Oxygen corrosion; MIC / under-deposit | G17: phase + material + fluid service + temperature band | H17: method must detect listed DM | I17: Preliminary DM; validate against P&ID, chemistry and baseline inspection.
A18: CL-SAGS-LBA-STEAM-CS-V-T1_BELOW_80C | B18: SAGS | C18: Steam | D18: V | E18: CS | F18: CUI; Atmospheric corrosion; Erosion (localized) | G18: phase + material + fluid service + temperature band | H18: method must detect listed DM | I18: Preliminary DM; validate against P&ID, chemistry and baseline inspection.
A19: CL-BOPUT-PAD-COOLINGWATER--L-T1_BELOW_80C | B19: BOP/Utility | C19: Cooling Water | D19: L | F19: Cooling water corrosion; MIC; Oxygen corrosion | G19: phase + material + fluid service + temperature band | H19: method must detect listed DM | I19: Preliminary DM; validate against P&ID, chemistry and baseline inspection.
A20: EQ-POWER-MAJ-EQUIPMENT | B20: Power Block | F20: General external corrosion; CUI if insulated | G20: phase + material + fluid service + temperature band | H20: method must detect listed DM | I20: Preliminary DM; validate against P&ID, chemistry and baseline inspection.
A21: CL-SAGS-LBF-CONDENSATE-CS-L-T1_BELOW_80C | B21: SAGS | C21: Condensate | D21: L | E21: CS | F21: CO2 condensate corrosion; Oxygen corrosion; MIC / under-deposit | G21: phase + material + fluid service + temperature band | H21: method must detect listed DM | I21: Preliminary DM; validate against P&ID, chemistry and baseline inspection.
A22: CL-BOPUT-PAD-COOLINGWATER-SS316L-L-T1_BELOW_80C | B22: BOP/Utility | C22: Cooling Water | D22: L | E22: SS316L | F22: Cooling water corrosion; MIC; Oxygen corrosion | G22: phase + material + fluid service + temperature band | H22: method must detect listed DM | I22: Preliminary DM; validate against P&ID, chemistry and baseline inspection.
A23: EQ-POWER-MAV-EQUIPMENT | B23: Power Block | F23: General external corrosion; CUI if insulated | G23: phase + material + fluid service + temperature band | H23: method must detect listed DM | I23: Preliminary DM; validate against P&ID, chemistry and baseline inspection.
A24: CL-SAGS-LCM-CONDENSATE-CS-L-T1_BELOW_80C | B24: SAGS | C24: Condensate | D24: L | E24: CS | F24: CO2 condensate corrosion; Oxygen corrosion; MIC / under-deposit | G24: phase + material + fluid service + temperature band | H24: method must detect listed DM | I24: Preliminary DM; validate against P&ID, chemistry and baseline inspection.
A25: CL-POWER-LBG-STEAM-CS-V-T3_150C_PLUS | B25: Power Block | C25: Steam | D25: V | E25: CS | F25: CUI; Atmospheric corrosion; Erosion (localized) | G25: phase + material + fluid service + temperature band | H25: method must detect listed DM | I25: Preliminary DM; validate against P&ID, chemistry and baseline inspection.
A26: CL-BOPUT-PAE-COOLINGWATER-SS316L-L-T1_BELOW_80C | B26: BOP/Utility | C26: Cooling Water | D26: L | E26: SS316L | F26: Cooling water corrosion; MIC; Oxygen corrosion | G26: phase + material + fluid service + temperature band | H26: method must detect listed DM | I26: Preliminary DM; validate against P&ID, chemistry and baseline inspection.
A27: CL-BOPUT-PCB-SEALWATER-SS316L-L-T1_BELOW_80C | B27: BOP/Utility | C27: Seal Water | D27: L | E27: SS316L | F27: Oxygen corrosion; MIC | G27: phase + material + fluid service + temperature band | H27: method must detect listed DM | I27: Preliminary DM; validate against P&ID, chemistry and baseline inspection.
A28: EQ-POWER-MAV-STATICEQUIPMENT | B28: Power Block | E28: SS316L | F28: General external corrosion; CUI if insulated | G28: phase + material + fluid service + temperature band | H28: method must detect listed DM | I28: Preliminary DM; validate against P&ID, chemistry and baseline inspection.
A29: CL-BOPUT-PAB-STEAMWASH-SS316L-L-T0_UNKNOWN | B29: BOP/Utility | C29: Steam Wash | D29: L | E29: SS316L | F29: CO2 condensate corrosion; Oxygen corrosion; MIC / under-deposit | G29: phase + material + fluid service + temperature band | H29: method must detect listed DM | I29: Preliminary DM; validate against P&ID, chemistry and baseline inspection.
A30: CL-BOPUT-PAB-CONDENSATE-SS316L-L-T1_BELOW_80C | B30: BOP/Utility | C30: Condensate | D30: L | E30: SS316L | F30: CO2 condensate corrosion; Oxygen corrosion; MIC / under-deposit | G30: phase + material + fluid service + temperature band | H30: method must detect listed DM | I30: Preliminary DM; validate against P&ID, chemistry and baseline inspection.
A31: CL-BOPUT-PCB-COOLINGWATER-SS316L-L-T1_BELOW_80C | B31: BOP/Utility | C31: Cooling Water | D31: L | E31: SS316L | F31: Cooling water corrosion; MIC; Oxygen corrosion | G31: phase + material + fluid service + temperature band | H31: method must detect listed DM | I31: Preliminary DM; validate against P&ID, chemistry and baseline inspection.
A32: CL-BOPUT-QCH--CS--T1_BELOW_80C | B32: BOP/Utility | E32: CS | F32: General external corrosion; CUI if insulated | G32: phase + material + fluid service + temperature band | H32: method must detect listed DM | I32: Preliminary DM; validate against P&ID, chemistry and baseline inspection.
A33: EQ-SAGS-LBF-CIVILSTATIC | B33: SAGS | E33: CARBON STEEL | F33: General external corrosion; CUI if insulated | G33: phase + material + fluid service + temperature band | H33: method must detect listed DM | I33: Preliminary DM; validate against P&ID, chemistry and baseline inspection.
A34: EQ-BOPUT-QEA-STATICEQUIPMENT | B34: BOP/Utility | E34: SS304L | F34: General external corrosion; CUI if insulated | G34: phase + material + fluid service + temperature band | H34: method must detect listed DM | I34: Preliminary DM; validate against P&ID, chemistry and baseline inspection.
A35: CL-POWER-LBG-STEAM-CS-V-T1_BELOW_80C | B35: Power Block | C35: Steam | D35: V | E35: CS | F35: CUI; Atmospheric corrosion; Erosion (localized) | G35: phase + material + fluid service + temperature band | H35: method must detect listed DM | I35: Preliminary DM; validate against P&ID, chemistry and baseline inspection.
A36: CL-SAGS-LBA-STEAM--V-T3_150C_PLUS | B36: SAGS | C36: Steam | D36: V | F36: CUI; Atmospheric corrosion; Erosion (localized) | G36: phase + material + fluid service + temperature band | H36: method must detect listed DM | I36: Preliminary DM; validate against P&ID, chemistry and baseline inspection.
A37: CL-POWER-MAW-GLANDSTEAM-SS316L-V-T2_80_150C | B37: Power Block | C37: Gland Steam | D37: V | E37: SS316L | F37: CUI; Atmospheric corrosion; Erosion (localized) | G37: phase + material + fluid service + temperature band | H37: method must detect listed DM | I37: Preliminary DM; validate against P&ID, chemistry and baseline inspection.
A38: CL-BOPUT-PAB-SPRAYWATER-SS316L-L-T0_UNKNOWN | B38: BOP/Utility | C38: Spray Water | D38: L | E38: SS316L | F38: Oxygen corrosion; MIC | G38: phase + material + fluid service + temperature band | H38: method must detect listed DM | I38: Preliminary DM; validate against P&ID, chemistry and baseline inspection.
A39: CL-POWER-MAW-GLANDSTEAM-SS316L-L-T1_BELOW_80C | B39: Power Block | C39: Gland Steam | D39: L | E39: SS316L | F39: General external corrosion; CUI if insulated | G39: phase + material + fluid service + temperature band | H39: method must detect listed DM | I39: Preliminary DM; validate against P&ID, chemistry and baseline inspection.
A40: CL-POWER-MAJ-NCG-SS316L-V-T1_BELOW_80C | B40: Power Block | C40: NCG | D40: V | E40: SS316L | F40: H2S / sour corrosion; CLSCC (if chloride + SS); Atmospheric/CUI | G40: phase + material + fluid service + temperature band | H40: method must detect listed DM | I40: Preliminary DM; validate against P&ID, chemistry and baseline inspection.
A41: CL-POWER-MAJ-COOLINGWATER--L-T1_BELOW_80C | B41: Power Block | C41: Cooling Water | D41: L | F41: Cooling water corrosion; MIC; Oxygen corrosion | G41: phase + material + fluid service + temperature band | H41: method must detect listed DM | I41: Preliminary DM; validate against P&ID, chemistry and baseline inspection.
...

Sheet 06_POF_ENGINE
A1: 06 PoF Engine - Preliminary Semi-Quantitative
A3: Asset Tag | B3: Corrosion Loop ID | C3: Fluid | D3: State | E3: Material | F3: Dominant DM | G3: PoF Score | H3: PoF Basis
A4: P2LBA11 BR001 | B4: CL-SAGS-LBA-STEAM-CS-LG-T3_150C_PLUS | C4: Steam | D4: LG | E4: CS | F4: CO2 corrosion; Erosion-corrosion / FAC; CUI | G4: 4 | H4: Rule-based preliminary score from DM susceptibility; replace with L3 calculation after UT/CR data.
A5: P2LBA11 BR501 | B5: CL-SAGS-LBA-STEAM-CS-LG-T3_150C_PLUS | C5: Steam | D5: LG | E5: CS | F5: CO2 corrosion; Erosion-corrosion / FAC; CUI | G5: 4 | H5: Rule-based preliminary score from DM susceptibility; replace with L3 calculation after UT/CR data.
A6: P2LBA11 BR011 | B6: CL-SAGS-LBA-STEAM-CS-LG-T3_150C_PLUS | C6: Steam | D6: LG | E6: CS | F6: CO2 corrosion; Erosion-corrosion / FAC; CUI | G6: 4 | H6: Rule-based preliminary score from DM susceptibility; replace with L3 calculation after UT/CR data.
A7: P2LBA11 BR003 | B7: CL-SAGS-LBA-STEAM-CS-LG-T3_150C_PLUS | C7: Steam | D7: LG | E7: CS | F7: CO2 corrosion; Erosion-corrosion / FAC; CUI | G7: 4 | H7: Rule-based preliminary score from DM susceptibility; replace with L3 calculation after UT/CR data.
A8: P2LBA11 BR010 | B8: CL-SAGS-LBA-STEAM-CS-LG-T3_150C_PLUS | C8: Steam | D8: LG | E8: CS | F8: CO2 corrosion; Erosion-corrosion / FAC; CUI | G8: 4 | H8: Rule-based preliminary score from DM susceptibility; replace with L3 calculation after UT/CR data.
A9: P2LBA11 BR301 | B9: CL-SAGS-LBA-STEAM-CS-LG-T3_150C_PLUS | C9: Steam | D9: LG | E9: CS | F9: CO2 corrosion; Erosion-corrosion / FAC; CUI | G9: 4 | H9: Rule-based preliminary score from DM susceptibility; replace with L3 calculation after UT/CR data.
A10: P2LBA12 BR001 | B10: CL-SAGS-LBA-STEAM-CS-V-T3_150C_PLUS | C10: Steam | D10: V | E10: CS | F10: CUI; Atmospheric corrosion; Erosion (localized) | G10: 2 | H10: Rule-based preliminary score from DM susceptibility; replace with L3 calculation after UT/CR data.
